Traceback (most recent call last):
  File "/Users/corrado/mambaforge/envs/pymc_env/lib/python3.11/site-packages/jupyter_cache/executors/utils.py", line 58, in single_nb_execution
    executenb(
  File "/Users/corrado/mambaforge/envs/pymc_env/lib/python3.11/site-packages/nbclient/client.py", line 1204, in execute
    return NotebookClient(nb=nb, resources=resources, km=km, **kwargs).execute()
           ^^^^^^^^^^^^^^^^^^^^^^^^^^^^^^^^^^^^^^^^^^^^^^^^^^^^^^^^^^^^^^^^^^^^^
  File "/Users/corrado/mambaforge/envs/pymc_env/lib/python3.11/site-packages/nbclient/util.py", line 84, in wrapped
    return just_run(coro(*args, **kwargs))
           ^^^^^^^^^^^^^^^^^^^^^^^^^^^^^^^
  File "/Users/corrado/mambaforge/envs/pymc_env/lib/python3.11/site-packages/nbclient/util.py", line 62, in just_run
    return loop.run_until_complete(coro)
           ^^^^^^^^^^^^^^^^^^^^^^^^^^^^^
  File "/Users/corrado/mambaforge/envs/pymc_env/lib/python3.11/asyncio/base_events.py", line 653, in run_until_complete
    return future.result()
           ^^^^^^^^^^^^^^^
  File "/Users/corrado/mambaforge/envs/pymc_env/lib/python3.11/site-packages/nbclient/client.py", line 663, in async_execute
    await self.async_execute_cell(
  File "/Users/corrado/mambaforge/envs/pymc_env/lib/python3.11/site-packages/nbclient/client.py", line 965, in async_execute_cell
    await self._check_raise_for_error(cell, cell_index, exec_reply)
  File "/Users/corrado/mambaforge/envs/pymc_env/lib/python3.11/site-packages/nbclient/client.py", line 862, in _check_raise_for_error
    raise CellExecutionError.from_cell_and_msg(cell, exec_reply_content)
nbclient.exceptions.CellExecutionError: An error occurred while executing the following cell:
------------------
set.seed(2237) # setting the seed ensure reproducibility
num_person <- 1000 # number of respondents
# True scores for Test 1
t1 <- rnorm(num_person, mean = 20, sd = 5)
# Error scores for Test 1
e1 <- rnorm(num_person, mean = 0, sd = 2)
# Observed scores for Test 1
x1 <- t1 + e1
# True scores for Test 2
t2 <- t1 # parallel tests have equal true scores
# Error scores for Test 2
e2 <- rnorm(num_person, mean = 0, sd = 2)
# Observed scores for Test 2
x2 <- t2 + e2

# Merge into a data frame
test_df <- data.frame(x1, x2)

mv <- datasummary(x1 + x2 ~ Mean + Var,
    data = test_df,
    output = "data.frame"
)
mv
------------------

Error in datasummary(x1 + x2 ~ Mean + Var, data = test_df, output = "data.frame"): could not find function "datasummary"
Traceback:

ERROR: Error in datasummary(x1 + x2 ~ Mean + Var, data = test_df, output = "data.frame"): could not find function "datasummary"


