Traceback (most recent call last):
  File "/Users/corrado/opt/anaconda3/envs/pymc_env/lib/python3.11/site-packages/jupyter_cache/executors/utils.py", line 58, in single_nb_execution
    executenb(
  File "/Users/corrado/opt/anaconda3/envs/pymc_env/lib/python3.11/site-packages/nbclient/client.py", line 1305, in execute
    return NotebookClient(nb=nb, resources=resources, km=km, **kwargs).execute()
           ^^^^^^^^^^^^^^^^^^^^^^^^^^^^^^^^^^^^^^^^^^^^^^^^^^^^^^^^^^^^^^^^^^^^^
  File "/Users/corrado/opt/anaconda3/envs/pymc_env/lib/python3.11/site-packages/jupyter_core/utils/__init__.py", line 173, in wrapped
    return loop.run_until_complete(inner)
           ^^^^^^^^^^^^^^^^^^^^^^^^^^^^^^
  File "/Users/corrado/opt/anaconda3/envs/pymc_env/lib/python3.11/asyncio/base_events.py", line 653, in run_until_complete
    return future.result()
           ^^^^^^^^^^^^^^^
  File "/Users/corrado/opt/anaconda3/envs/pymc_env/lib/python3.11/site-packages/nbclient/client.py", line 705, in async_execute
    await self.async_execute_cell(
  File "/Users/corrado/opt/anaconda3/envs/pymc_env/lib/python3.11/site-packages/nbclient/client.py", line 1058, in async_execute_cell
    await self._check_raise_for_error(cell, cell_index, exec_reply)
  File "/Users/corrado/opt/anaconda3/envs/pymc_env/lib/python3.11/site-packages/nbclient/client.py", line 914, in _check_raise_for_error
    raise CellExecutionError.from_cell_and_msg(cell, exec_reply_content)
nbclient.exceptions.CellExecutionError: An error occurred while executing the following cell:
------------------
slp_dat <- read.csv("https://osf.io/download/p9gqk/")
slp_vas_wide <- slp_dat |>
    select(slpID, Speaker, slp_VAS) |>
    pivot_wider(names_from = slpID, values_from = slp_VAS)
head(slp_vas_wide)
------------------

----- stderr -----
Warning message in file(file, "rt"):
“URL 'https://files.osf.io/v1/resources/sr9aw/providers/github/Manuscript%20Analysis/Shared%20Data/SLP_Correlation.csv': lo status era 'Couldn't connect to server'”
------------------

Error in file(file, "rt"): non è possibile aprire la connessione a 'https://osf.io/download/p9gqk/'
Traceback:

1. read.csv("https://osf.io/download/p9gqk/")
2. read.table(file = file, header = header, sep = sep, quote = quote, 
 .     dec = dec, fill = fill, comment.char = comment.char, ...)
3. file(file, "rt")

