Traceback (most recent call last):
  File "/Users/corrado/mambaforge/envs/pymc_env/lib/python3.11/site-packages/jupyter_cache/executors/utils.py", line 58, in single_nb_execution
    executenb(
  File "/Users/corrado/mambaforge/envs/pymc_env/lib/python3.11/site-packages/nbclient/client.py", line 1204, in execute
    return NotebookClient(nb=nb, resources=resources, km=km, **kwargs).execute()
           ^^^^^^^^^^^^^^^^^^^^^^^^^^^^^^^^^^^^^^^^^^^^^^^^^^^^^^^^^^^^^^^^^^^^^
  File "/Users/corrado/mambaforge/envs/pymc_env/lib/python3.11/site-packages/nbclient/util.py", line 84, in wrapped
    return just_run(coro(*args, **kwargs))
           ^^^^^^^^^^^^^^^^^^^^^^^^^^^^^^^
  File "/Users/corrado/mambaforge/envs/pymc_env/lib/python3.11/site-packages/nbclient/util.py", line 62, in just_run
    return loop.run_until_complete(coro)
           ^^^^^^^^^^^^^^^^^^^^^^^^^^^^^
  File "/Users/corrado/mambaforge/envs/pymc_env/lib/python3.11/asyncio/base_events.py", line 653, in run_until_complete
    return future.result()
           ^^^^^^^^^^^^^^^
  File "/Users/corrado/mambaforge/envs/pymc_env/lib/python3.11/site-packages/nbclient/client.py", line 663, in async_execute
    await self.async_execute_cell(
  File "/Users/corrado/mambaforge/envs/pymc_env/lib/python3.11/site-packages/nbclient/client.py", line 965, in async_execute_cell
    await self._check_raise_for_error(cell, cell_index, exec_reply)
  File "/Users/corrado/mambaforge/envs/pymc_env/lib/python3.11/site-packages/nbclient/client.py", line 862, in _check_raise_for_error
    raise CellExecutionError.from_cell_and_msg(cell, exec_reply_content)
nbclient.exceptions.CellExecutionError: An error occurred while executing the following cell:
------------------
mod_4 <- "
    # SitP loadings (all estimated)
    SitP =~ HFS14 + HFS16 + HFS18
    # SitN loadings (all estimated)
    SitN =~ HFS13 + HFS15 + HFS17
"
fit_4 <- sem(model = mod_4, data = hfs_situations, estimator = "MLR", mimic = "mplus", std.lv = TRUE)
print(
    summary(model04Estimates, fit.measures = TRUE, rsquare = TRUE, standardized = TRUE)
)
------------------

Error in h(simpleError(msg, call)): error in evaluating the argument 'object' in selecting a method for function 'summary': object 'model04Estimates' not found
Traceback:

1. print(summary(model04Estimates, fit.measures = TRUE, rsquare = TRUE, 
 .     standardized = TRUE))
2. summary(model04Estimates, fit.measures = TRUE, rsquare = TRUE, 
 .     standardized = TRUE)
3. .handleSimpleError(function (cond) 
 . .Internal(C_tryCatchHelper(addr, 1L, cond)), "object 'model04Estimates' not found", 
 .     base::quote(eval(expr, envir, enclos)))
4. h(simpleError(msg, call))
ERROR: Error in h(simpleError(msg, call)): error in evaluating the argument 'object' in selecting a method for function 'summary': object 'model04Estimates' not found


